Workbook

Sheet Dashboard
B1: MarketPulse | Service Marketplace Operations Dashboard
B2: Orders 20 Oct – 27 Oct 2026 · source: marketplace_orders export (DBeaver) · all figures are live formulas over the Data sheet
B4: TOTAL ORDERS | D4: FULFILLMENT RATE | F4: CANCELLATION RATE | H4: NO-PARTNER ORDERS | J4: AVG TURNAROUND (MIN)
B5: =Category!B9 -> 1000 | D5: =Category!E9 -> 0.864 | F5: =Category!H9 -> 0.136 | H5: =Category!J9 -> 0.083 | J5: =Category!L9 -> 38.795139
B7: SLA BREACH RATE | D7: AVG CUSTOMER RATING | F7: GMV BOOKED | H7: REVENUE AT RISK | J7: CRITICAL ALERTS
B8: =Category!N9 -> 0.023148148 | D8: =Category!O9 -> 4.2222222 | F8: =Category!P9 -> 802398.17 | H8: =Category!Q9 -> 105659.57 | J8: =Alerts!E4 -> 4
B41: Key findings (snapshot of this export, generated from the SQL results)
B42: 1. Zone East is the problem zone. 259 orders, 16.2% with no partner (other zones 4.8–6.4%) and all 20 SLA breaches in the export (9.3% breach rate vs 0% elsewhere).
B43: 2. It is a night-shift supply gap. Zone East 00–05h: 36.7% unassigned (90 orders) and a 28.6% SLA breach rate. Every breach falls between 02:00 and 04:59 with TAT of 66–95 min.
B44: 3. Night (00–05h) is the busiest window: 38.4% of all orders and the weakest coverage (12.5% unassigned). By category: Home Cleaning 16.1%, Salon Services 13.0%, Plumbing 10.5%, Appliance Repair 10.2%. Plumbing also dips in the evening (12.9% at 17–20h).
B45: 4. Cancellations are a supply symptom: all 56 provider cancellations were on orders that never had a partner. Revenue at risk from cancelled orders: 105,660 (13.6% of orders).
B46: 5. Suggested action: add or incentivise Zone East partners for 02:00–05:00, then re-check this dashboard. Verify first that order_hour is local time (if it is UTC, the 'night' peak is actually early morning in India).

Sheet Category
A1: Category scorecard
A2: Demand, fulfillment, supply and SLA health per service category
A4: Service category | B4: Orders | C4: Demand share | D4: Completed | E4: Fulfillment % | F4: Cust. cancelled | G4: Provider cancelled | H4: Cancellation % | I4: No-partner orders | J4: Unassigned % | K4: Partner availability % | L4: Avg TAT (min) | M4: SLA breaches | N4: SLA breach % | O4: Avg rating | P4: GMV booked | Q4: Revenue at risk
A5: Appliance Repair | B5: =COUNTIFS(d_cat,$A5) -> 226 | C5: =B5/B$9 -> 0.226 | D5: =COUNTIFS(d_cat,$A5,d_status,"Completed") -> 193 | E5: =IFERROR(D5/B5,0) -> 0.8539823 | F5: =COUNTIFS(d_cat,$A5,d_status,"Cancelled_Customer") -> 18 | G5: =COUNTIFS(d_cat,$A5,d_status,"Cancelled_Provider") -> 15 | H5: =IFERROR((F5+G5)/B5,0) -> 0.1460177 | I5: =COUNTIFS(d_cat,$A5,d_assigned,FALSE()) -> 19 | J5: =IFERROR(I5/B5,0) -> 0.084070796 | K5: =1-J5 -> 0.9159292 | L5: =IFERROR(AVERAGEIFS(d_tat,d_cat,$A5),0) -> 40.025907 | M5: =SUMIFS(d_sla,d_cat,$A5) -> 5 | N5: =IFERROR(M5/D5,0) -> 0.025906736 | O5: =IFERROR(AVERAGEIFS(d_rating,d_cat,$A5),0) -> 4.2435233 | P5: =SUMIFS(d_value,d_cat,$A5) -> 145556.4 | Q5: =SUMIFS(d_value,d_cat,$A5,d_status,"Cancelled*") -> 21485.21
A6: Home Cleaning | B6: =COUNTIFS(d_cat,$A6) -> 255 | C6: =B6/B$9 -> 0.255 | D6: =COUNTIFS(d_cat,$A6,d_status,"Completed") -> 224 | E6: =IFERROR(D6/B6,0) -> 0.87843137 | F6: =COUNTIFS(d_cat,$A6,d_status,"Cancelled_Customer") -> 18 | G6: =COUNTIFS(d_cat,$A6,d_status,"Cancelled_Provider") -> 13 | H6: =IFERROR((F6+G6)/B6,0) -> 0.12156863 | I6: =COUNTIFS(d_cat,$A6,d_assigned,FALSE()) -> 23 | J6: =IFERROR(I6/B6,0) -> 0.090196078 | K6: =1-J6 -> 0.90980392 | L6: =IFERROR(AVERAGEIFS(d_tat,d_cat,$A6),0) -> 38.361607 | M6: =SUMIFS(d_sla,d_cat,$A6) -> 5 | N6: =IFERROR(M6/D6,0) -> 0.022321429 | O6: =IFERROR(AVERAGEIFS(d_rating,d_cat,$A6),0) -> 4.1964286 | P6: =SUMIFS(d_value,d_cat,$A6) -> 292986.26 | Q6: =SUMIFS(d_value,d_cat,$A6,d_status,"Cancelled*") -> 35406.24
A7: Plumbing | B7: =COUNTIFS(d_cat,$A7) -> 259 | C7: =B7/B$9 -> 0.259 | D7: =COUNTIFS(d_cat,$A7,d_status,"Completed") -> 220 | E7: =IFERROR(D7/B7,0) -> 0.84942085 | F7: =COUNTIFS(d_cat,$A7,d_status,"Cancelled_Customer") -> 24 | G7: =COUNTIFS(d_cat,$A7,d_status,"Cancelled_Provider") -> 15 | H7: =IFERROR((F7+G7)/B7,0) -> 0.15057915 | I7: =COUNTIFS(d_cat,$A7,d_assigned,FALSE()) -> 21 | J7: =IFERROR(I7/B7,0) -> 0.081081081 | K7: =1-J7 -> 0.91891892 | L7: =IFERROR(AVERAGEIFS(d_tat,d_cat,$A7),0) -> 37.745455 | M7: =SUMIFS(d_sla,d_cat,$A7) -> 5 | N7: =IFERROR(M7/D7,0) -> 0.022727273 | O7: =IFERROR(AVERAGEIFS(d_rating,d_cat,$A7),0) -> 4.1772727 | P7: =SUMIFS(d_value,d_cat,$A7) -> 130667.37 | Q7: =SUMIFS(d_value,d_cat,$A7,d_status,"Cancelled*") -> 19678.16
A8: Salon Services | B8: =COUNTIFS(d_cat,$A8) -> 260 | C8: =B8/B$9 -> 0.26 | D8: =COUNTIFS(d_cat,$A8,d_status,"Completed") -> 227 | E8: =IFERROR(D8/B8,0) -> 0.87307692 | F8: =COUNTIFS(d_cat,$A8,d_status,"Cancelled_Customer") -> 20 | G8: =COUNTIFS(d_cat,$A8,d_status,"Cancelled_Provider") -> 13 | H8: =IFERROR((F8+G8)/B8,0) -> 0.12692308 | I8: =COUNTIFS(d_cat,$A8,d_assigned,FALSE()) -> 20 | J8: =IFERROR(I8/B8,0) -> 0.076923077 | K8: =1-J8 -> 0.92307692 | L8: =IFERROR(AVERAGEIFS(d_tat,d_cat,$A8),0) -> 39.193833 | M8: =SUMIFS(d_sla,d_cat,$A8) -> 5 | N8: =IFERROR(M8/D8,0) -> 0.022026432 | O8: =IFERROR(AVERAGEIFS(d_rating,d_cat,$A8),0) -> 4.2731278 | P8: =SUMIFS(d_value,d_cat,$A8) -> 233188.14 | Q8: =SUMIFS(d_value,d_cat,$A8,d_status,"Cancelled*") -> 29089.96
A9: Total | B9: =SUM(B5:B8) -> 1000 | C9: =SUM(C5:C8) -> 1 | D9: =SUM(D5:D8) -> 864 | E9: =IFERROR(D9/B9,0) -> 0.864 | F9: =SUM(F5:F8) -> 80 | G9: =SUM(G5:G8) -> 56 | H9: =IFERROR((F9+G9)/B9,0) -> 0.136 | I9: =SUM(I5:I8) -> 83 | J9: =IFERROR(I9/B9,0) -> 0.083 | K9: =1-J9 -> 0.917 | L9: =AVERAGE(d_tat) -> 38.795139 | M9: =SUM(M5:M8) -> 20 | N9: =IFERROR(M9/D9,0) -> 0.023148148 | O9: =AVERAGE(d_rating) -> 4.2222222 | P9: =SUM(P5:P8) -> 802398.17 | Q9: =SUM(Q5:Q8) -> 105659.57
A11: Definitions: Fulfillment = Completed ÷ Orders · Cancellation = (Customer + Provider) ÷ Orders · Unassigned = orders with no partner ÷ Orders · Avg TAT & SLA breach % use COMPLETED orders only (TAT exists only for them) · Revenue at risk = order value of cancelled orders.

Sheet Zone
A1: Zone scorecard
A2: Same KPIs per city zone
A4: City zone | B4: Orders | C4: Demand share | D4: Completed | E4: Fulfillment % | F4: Cust. cancelled | G4: Provider cancelled | H4: Cancellation % | I4: No-partner orders | J4: Unassigned % | K4: Partner availability % | L4: Avg TAT (min) | M4: SLA breaches | N4: SLA breach % | O4: Avg rating | P4: GMV booked | Q4: Revenue at risk
A5: Zone East | B5: =COUNTIFS(d_zone,$A5) -> 259 | C5: =B5/B$9 -> 0.259 | D5: =COUNTIFS(d_zone,$A5,d_status,"Completed") -> 215 | E5: =IFERROR(D5/B5,0) -> 0.83011583 | F5: =COUNTIFS(d_zone,$A5,d_status,"Cancelled_Customer") -> 29 | G5: =COUNTIFS(d_zone,$A5,d_status,"Cancelled_Provider") -> 15 | H5: =IFERROR((F5+G5)/B5,0) -> 0.16988417 | I5: =COUNTIFS(d_zone,$A5,d_assigned,FALSE()) -> 42 | J5: =IFERROR(I5/B5,0) -> 0.16216216 | K5: =1-J5 -> 0.83783784 | L5: =IFERROR(AVERAGEIFS(d_tat,d_zone,$A5),0) -> 41.967442 | M5: =SUMIFS(d_sla,d_zone,$A5) -> 20 | N5: =IFERROR(M5/D5,0) -> 0.093023256 | O5: =IFERROR(AVERAGEIFS(d_rating,d_zone,$A5),0) -> 4.1209302 | P5: =SUMIFS(d_value,d_zone,$A5) -> 207003.26 | Q5: =SUMIFS(d_value,d_zone,$A5,d_status,"Cancelled*") -> 32904.61
A6: Zone North | B6: =COUNTIFS(d_zone,$A6) -> 250 | C6: =B6/B$9 -> 0.25 | D6: =COUNTIFS(d_zone,$A6,d_status,"Completed") -> 223 | E6: =IFERROR(D6/B6,0) -> 0.892 | F6: =COUNTIFS(d_zone,$A6,d_status,"Cancelled_Customer") -> 11 | G6: =COUNTIFS(d_zone,$A6,d_status,"Cancelled_Provider") -> 16 | H6: =IFERROR((F6+G6)/B6,0) -> 0.108 | I6: =COUNTIFS(d_zone,$A6,d_assigned,FALSE()) -> 16 | J6: =IFERROR(I6/B6,0) -> 0.064 | K6: =1-J6 -> 0.936 | L6: =IFERROR(AVERAGEIFS(d_tat,d_zone,$A6),0) -> 38.587444 | M6: =SUMIFS(d_sla,d_zone,$A6) -> 0 | N6: =IFERROR(M6/D6,0) -> 0 | O6: =IFERROR(AVERAGEIFS(d_rating,d_zone,$A6),0) -> 4.206278 | P6: =SUMIFS(d_value,d_zone,$A6) -> 197403.34 | Q6: =SUMIFS(d_value,d_zone,$A6,d_status,"Cancelled*") -> 19680.71
A7: Zone South | B7: =COUNTIFS(d_zone,$A7) -> 231 | C7: =B7/B$9 -> 0.231 | D7: =COUNTIFS(d_zone,$A7,d_status,"Completed") -> 198 | E7: =IFERROR(D7/B7,0) -> 0.85714286 | F7: =COUNTIFS(d_zone,$A7,d_status,"Cancelled_Customer") -> 22 | G7: =COUNTIFS(d_zone,$A7,d_status,"Cancelled_Provider") -> 11 | H7: =IFERROR((F7+G7)/B7,0) -> 0.14285714 | I7: =COUNTIFS(d_zone,$A7,d_assigned,FALSE()) -> 11 | J7: =IFERROR(I7/B7,0) -> 0.047619048 | K7: =1-J7 -> 0.95238095 | L7: =IFERROR(AVERAGEIFS(d_tat,d_zone,$A7),0) -> 36.969697 | M7: =SUMIFS(d_sla,d_zone,$A7) -> 0 | N7: =IFERROR(M7/D7,0) -> 0 | O7: =IFERROR(AVERAGEIFS(d_rating,d_zone,$A7),0) -> 4.2727273 | P7: =SUMIFS(d_value,d_zone,$A7) -> 183470.81 | Q7: =SUMIFS(d_value,d_zone,$A7,d_status,"Cancelled*") -> 26025.91
A8: Zone West | B8: =COUNTIFS(d_zone,$A8) -> 260 | C8: =B8/B$9 -> 0.26 | D8: =COUNTIFS(d_zone,$A8,d_status,"Completed") -> 228 | E8: =IFERROR(D8/B8,0) -> 0.87692308 | F8: =COUNTIFS(d_zone,$A8,d_status,"Cancelled_Customer") -> 18 | G8: =COUNTIFS(d_zone,$A8,d_status,"Cancelled_Provider") -> 14 | H8: =IFERROR((F8+G8)/B8,0) -> 0.12307692 | I8: =COUNTIFS(d_zone,$A8,d_assigned,FALSE()) -> 14 | J8: =IFERROR(I8/B8,0) -> 0.053846154 | K8: =1-J8 -> 0.94615385 | L8: =IFERROR(AVERAGEIFS(d_tat,d_zone,$A8),0) -> 37.592105 | M8: =SUMIFS(d_sla,d_zone,$A8) -> 0 | N8: =IFERROR(M8/D8,0) -> 0 | O8: =IFERROR(AVERAGEIFS(d_rating,d_zone,$A8),0) -> 4.2894737 | P8: =SUMIFS(d_value,d_zone,$A8) -> 214520.76 | Q8: =SUMIFS(d_value,d_zone,$A8,d_status,"Cancelled*") -> 27048.34
A9: Total | B9: =SUM(B5:B8) -> 1000 | C9: =SUM(C5:C8) -> 1 | D9: =SUM(D5:D8) -> 864 | E9: =IFERROR(D9/B9,0) -> 0.864 | F9: =SUM(F5:F8) -> 80 | G9: =SUM(G5:G8) -> 56 | H9: =IFERROR((F9+G9)/B9,0) -> 0.136 | I9: =SUM(I5:I8) -> 83 | J9: =IFERROR(I9/B9,0) -> 0.083 | K9: =1-J9 -> 0.917 | L9: =AVERAGE(d_tat) -> 38.795139 | M9: =SUM(M5:M8) -> 20 | N9: =IFERROR(M9/D9,0) -> 0.023148148 | O9: =AVERAGE(d_rating) -> 4.2222222 | P9: =SUM(P5:P8) -> 802398.17 | Q9: =SUM(Q5:Q8) -> 105659.57
A11: Definitions: Fulfillment = Completed ÷ Orders · Cancellation = (Customer + Provider) ÷ Orders · Unassigned = orders with no partner ÷ Orders · Avg TAT & SLA breach % use COMPLETED orders only (TAT exists only for them) · Revenue at risk = order value of cancelled orders.

Sheet Time Band
A1: Hourly profile & supply-gap heatmaps
A2: When does demand arrive, and when are there no partners to serve it?
A4: Hour | B4: Orders | C4: Share of orders | D4: No-partner orders | E4: Unassigned % | F4: Cancelled | G4: Cancellation % | H4: Avg TAT (min) | K4: Unassigned rate: Category × Time band
A5: 0 | B5: =COUNTIFS(d_hour,$A5) -> 79 | C5: =B5/SUM(B$5:B$28) -> 0.079 | D5: =COUNTIFS(d_hour,$A5,d_assigned,FALSE()) -> 3 | E5: =IFERROR(D5/B5,0) -> 0.037974684 | F5: =COUNTIFS(d_hour,$A5,d_status,"Cancelled*") -> 10 | G5: =IFERROR(F5/B5,0) -> 0.12658228 | H5: =IFERROR(AVERAGEIFS(d_tat,d_hour,$A5),0) -> 38.115942 | K5: Category | L5: Night (00-05) | M5: Morning (06-11) | N5: Afternoon (12-16) | O5: Evening (17-20) | P5: Late (21-23)
A6: 1 | B6: =COUNTIFS(d_hour,$A6) -> 102 | C6: =B6/SUM(B$5:B$28) -> 0.102 | D6: =COUNTIFS(d_hour,$A6,d_assigned,FALSE()) -> 6 | E6: =IFERROR(D6/B6,0) -> 0.058823529 | F6: =COUNTIFS(d_hour,$A6,d_status,"Cancelled*") -> 12 | G6: =IFERROR(F6/B6,0) -> 0.11764706 | H6: =IFERROR(AVERAGEIFS(d_tat,d_hour,$A6),0) -> 37.122222 | K6: Appliance Repair | L6: =IFERROR(COUNTIFS(d_cat,$K6,d_band,L$5,d_assigned,FALSE())/COUNTIFS(d_cat,$K6,d_band,L$5),0) -> 0.10227273 | M6: =IFERROR(COUNTIFS(d_cat,$K6,d_band,M$5,d_assigned,FALSE())/COUNTIFS(d_cat,$K6,d_band,M$5),0) -> 0.071428571 | N6: =IFERROR(COUNTIFS(d_cat,$K6,d_band,N$5,d_assigned,FALSE())/COUNTIFS(d_cat,$K6,d_band,N$5),0) -> 0.088888889 | O6: =IFERROR(COUNTIFS(d_cat,$K6,d_band,O$5,d_assigned,FALSE())/COUNTIFS(d_cat,$K6,d_band,O$5),0) -> 0.056603774 | P6: =IFERROR(COUNTIFS(d_cat,$K6,d_band,P$5,d_assigned,FALSE())/COUNTIFS(d_cat,$K6,d_band,P$5),0) -> 0.076923077
A7: 2 | B7: =COUNTIFS(d_hour,$A7) -> 91 | C7: =B7/SUM(B$5:B$28) -> 0.091 | D7: =COUNTIFS(d_hour,$A7,d_assigned,FALSE()) -> 19 | E7: =IFERROR(D7/B7,0) -> 0.20879121 | F7: =COUNTIFS(d_hour,$A7,d_status,"Cancelled*") -> 18 | G7: =IFERROR(F7/B7,0) -> 0.1978022 | H7: =IFERROR(AVERAGEIFS(d_tat,d_hour,$A7),0) -> 44.136986 | K7: Home Cleaning | L7: =IFERROR(COUNTIFS(d_cat,$K7,d_band,L$5,d_assigned,FALSE())/COUNTIFS(d_cat,$K7,d_band,L$5),0) -> 0.16129032 | M7: =IFERROR(COUNTIFS(d_cat,$K7,d_band,M$5,d_assigned,FALSE())/COUNTIFS(d_cat,$K7,d_band,M$5),0) -> 0.11764706 | N7: =IFERROR(COUNTIFS(d_cat,$K7,d_band,N$5,d_assigned,FALSE())/COUNTIFS(d_cat,$K7,d_band,N$5),0) -> 0.022727273 | O7: =IFERROR(COUNTIFS(d_cat,$K7,d_band,O$5,d_assigned,FALSE())/COUNTIFS(d_cat,$K7,d_band,O$5),0) -> 0.054545455 | P7: =IFERROR(COUNTIFS(d_cat,$K7,d_band,P$5,d_assigned,FALSE())/COUNTIFS(d_cat,$K7,d_band,P$5),0) -> 0.043478261
A8: 3 | B8: =COUNTIFS(d_hour,$A8) -> 70 | C8: =B8/SUM(B$5:B$28) -> 0.07 | D8: =COUNTIFS(d_hour,$A8,d_assigned,FALSE()) -> 10 | E8: =IFERROR(D8/B8,0) -> 0.14285714 | F8: =COUNTIFS(d_hour,$A8,d_status,"Cancelled*") -> 12 | G8: =IFERROR(F8/B8,0) -> 0.17142857 | H8: =IFERROR(AVERAGEIFS(d_tat,d_hour,$A8),0) -> 43.758621 | K8: Plumbing | L8: =IFERROR(COUNTIFS(d_cat,$K8,d_band,L$5,d_assigned,FALSE())/COUNTIFS(d_cat,$K8,d_band,L$5),0) -> 0.10526316 | M8: =IFERROR(COUNTIFS(d_cat,$K8,d_band,M$5,d_assigned,FALSE())/COUNTIFS(d_cat,$K8,d_band,M$5),0) -> 0 | N8: =IFERROR(COUNTIFS(d_cat,$K8,d_band,N$5,d_assigned,FALSE())/COUNTIFS(d_cat,$K8,d_band,N$5),0) -> 0.023809524 | O8: =IFERROR(COUNTIFS(d_cat,$K8,d_band,O$5,d_assigned,FALSE())/COUNTIFS(d_cat,$K8,d_band,O$5),0) -> 0.12857143 | P8: =IFERROR(COUNTIFS(d_cat,$K8,d_band,P$5,d_assigned,FALSE())/COUNTIFS(d_cat,$K8,d_band,P$5),0) -> 0.029411765
A9: 4 | B9: =COUNTIFS(d_hour,$A9) -> 30 | C9: =B9/SUM(B$5:B$28) -> 0.03 | D9: =COUNTIFS(d_hour,$A9,d_assigned,FALSE()) -> 7 | E9: =IFERROR(D9/B9,0) -> 0.23333333 | F9: =COUNTIFS(d_hour,$A9,d_status,"Cancelled*") -> 7 | G9: =IFERROR(F9/B9,0) -> 0.23333333 | H9: =IFERROR(AVERAGEIFS(d_tat,d_hour,$A9),0) -> 45.73913 | K9: Salon Services | L9: =IFERROR(COUNTIFS(d_cat,$K9,d_band,L$5,d_assigned,FALSE())/COUNTIFS(d_cat,$K9,d_band,L$5),0) -> 0.12962963 | M9: =IFERROR(COUNTIFS(d_cat,$K9,d_band,M$5,d_assigned,FALSE())/COUNTIFS(d_cat,$K9,d_band,M$5),0) -> 0.125 | N9: =IFERROR(COUNTIFS(d_cat,$K9,d_band,N$5,d_assigned,FALSE())/COUNTIFS(d_cat,$K9,d_band,N$5),0) -> 0.03030303 | O9: =IFERROR(COUNTIFS(d_cat,$K9,d_band,O$5,d_assigned,FALSE())/COUNTIFS(d_cat,$K9,d_band,O$5),0) -> 0.033898305 | P9: =IFERROR(COUNTIFS(d_cat,$K9,d_band,P$5,d_assigned,FALSE())/COUNTIFS(d_cat,$K9,d_band,P$5),0) -> 0.022727273
A10: 5 | B10: =COUNTIFS(d_hour,$A10) -> 12 | C10: =B10/SUM(B$5:B$28) -> 0.012 | D10: =COUNTIFS(d_hour,$A10,d_assigned,FALSE()) -> 3 | E10: =IFERROR(D10/B10,0) -> 0.25 | F10: =COUNTIFS(d_hour,$A10,d_status,"Cancelled*") -> 2 | G10: =IFERROR(F10/B10,0) -> 0.16666667 | H10: =IFERROR(AVERAGEIFS(d_tat,d_hour,$A10),0) -> 42.1
A11: 6 | B11: =COUNTIFS(d_hour,$A11) -> 25 | C11: =B11/SUM(B$5:B$28) -> 0.025 | D11: =COUNTIFS(d_hour,$A11,d_assigned,FALSE()) -> 3 | E11: =IFERROR(D11/B11,0) -> 0.12 | F11: =COUNTIFS(d_hour,$A11,d_status,"Cancelled*") -> 5 | G11: =IFERROR(F11/B11,0) -> 0.2 | H11: =IFERROR(AVERAGEIFS(d_tat,d_hour,$A11),0) -> 35.95
A12: 7 | B12: =COUNTIFS(d_hour,$A12) -> 3 | C12: =B12/SUM(B$5:B$28) -> 0.003 | D12: =COUNTIFS(d_hour,$A12,d_assigned,FALSE()) -> 0 | E12: =IFERROR(D12/B12,0) -> 0 | F12: =COUNTIFS(d_hour,$A12,d_status,"Cancelled*") -> 1 | G12: =IFERROR(F12/B12,0) -> 0.33333333 | H12: =IFERROR(AVERAGEIFS(d_tat,d_hour,$A12),0) -> 27.5 | K12: Orders: Category × Time band
A13: 8 | B13: =COUNTIFS(d_hour,$A13) -> 12 | C13: =B13/SUM(B$5:B$28) -> 0.012 | D13: =COUNTIFS(d_hour,$A13,d_assigned,FALSE()) -> 1 | E13: =IFERROR(D13/B13,0) -> 0.083333333 | F13: =COUNTIFS(d_hour,$A13,d_status,"Cancelled*") -> 1 | G13: =IFERROR(F13/B13,0) -> 0.083333333 | H13: =IFERROR(AVERAGEIFS(d_tat,d_hour,$A13),0) -> 35 | K13: Category | L13: Night (00-05) | M13: Morning (06-11) | N13: Afternoon (12-16) | O13: Evening (17-20) | P13: Late (21-23)
A14: 9 | B14: =COUNTIFS(d_hour,$A14) -> 6 | C14: =B14/SUM(B$5:B$28) -> 0.006 | D14: =COUNTIFS(d_hour,$A14,d_assigned,FALSE()) -> 0 | E14: =IFERROR(D14/B14,0) -> 0 | F14: =COUNTIFS(d_hour,$A14,d_status,"Cancelled*") -> 0 | G14: =IFERROR(F14/B14,0) -> 0 | H14: =IFERROR(AVERAGEIFS(d_tat,d_hour,$A14),0) -> 43 | K14: Appliance Repair | L14: =COUNTIFS(d_cat,$K14,d_band,L$13) -> 88 | M14: =COUNTIFS(d_cat,$K14,d_band,M$13) -> 14 | N14: =COUNTIFS(d_cat,$K14,d_band,N$13) -> 45 | O14: =COUNTIFS(d_cat,$K14,d_band,O$13) -> 53 | P14: =COUNTIFS(d_cat,$K14,d_band,P$13) -> 26
A15: 10 | B15: =COUNTIFS(d_hour,$A15) -> 4 | C15: =B15/SUM(B$5:B$28) -> 0.004 | D15: =COUNTIFS(d_hour,$A15,d_assigned,FALSE()) -> 1 | E15: =IFERROR(D15/B15,0) -> 0.25 | F15: =COUNTIFS(d_hour,$A15,d_status,"Cancelled*") -> 2 | G15: =IFERROR(F15/B15,0) -> 0.5 | H15: =IFERROR(AVERAGEIFS(d_tat,d_hour,$A15),0) -> 38 | K15: Home Cleaning | L15: =COUNTIFS(d_cat,$K15,d_band,L$13) -> 93 | M15: =COUNTIFS(d_cat,$K15,d_band,M$13) -> 17 | N15: =COUNTIFS(d_cat,$K15,d_band,N$13) -> 44 | O15: =COUNTIFS(d_cat,$K15,d_band,O$13) -> 55 | P15: =COUNTIFS(d_cat,$K15,d_band,P$13) -> 46
A16: 11 | B16: =COUNTIFS(d_hour,$A16) -> 15 | C16: =B16/SUM(B$5:B$28) -> 0.015 | D16: =COUNTIFS(d_hour,$A16,d_assigned,FALSE()) -> 0 | E16: =IFERROR(D16/B16,0) -> 0 | F16: =COUNTIFS(d_hour,$A16,d_status,"Cancelled*") -> 0 | G16: =IFERROR(F16/B16,0) -> 0 | H16: =IFERROR(AVERAGEIFS(d_tat,d_hour,$A16),0) -> 38.8 | K16: Plumbing | L16: =COUNTIFS(d_cat,$K16,d_band,L$13) -> 95 | M16: =COUNTIFS(d_cat,$K16,d_band,M$13) -> 18 | N16: =COUNTIFS(d_cat,$K16,d_band,N$13) -> 42 | O16: =COUNTIFS(d_cat,$K16,d_band,O$13) -> 70 | P16: =COUNTIFS(d_cat,$K16,d_band,P$13) -> 34
A17: 12 | B17: =COUNTIFS(d_hour,$A17) -> 13 | C17: =B17/SUM(B$5:B$28) -> 0.013 | D17: =COUNTIFS(d_hour,$A17,d_assigned,FALSE()) -> 1 | E17: =IFERROR(D17/B17,0) -> 0.076923077 | F17: =COUNTIFS(d_hour,$A17,d_status,"Cancelled*") -> 1 | G17: =IFERROR(F17/B17,0) -> 0.076923077 | H17: =IFERROR(AVERAGEIFS(d_tat,d_hour,$A17),0) -> 40.666667 | K17: Salon Services | L17: =COUNTIFS(d_cat,$K17,d_band,L$13) -> 108 | M17: =COUNTIFS(d_cat,$K17,d_band,M$13) -> 16 | N17: =COUNTIFS(d_cat,$K17,d_band,N$13) -> 33 | O17: =COUNTIFS(d_cat,$K17,d_band,O$13) -> 59 | P17: =COUNTIFS(d_cat,$K17,d_band,P$13) -> 44
A18: 13 | B18: =COUNTIFS(d_hour,$A18) -> 17 | C18: =B18/SUM(B$5:B$28) -> 0.017 | D18: =COUNTIFS(d_hour,$A18,d_assigned,FALSE()) -> 0 | E18: =IFERROR(D18/B18,0) -> 0 | F18: =COUNTIFS(d_hour,$A18,d_status,"Cancelled*") -> 2 | G18: =IFERROR(F18/B18,0) -> 0.11764706 | H18: =IFERROR(AVERAGEIFS(d_tat,d_hour,$A18),0) -> 33.333333
A19: 14 | B19: =COUNTIFS(d_hour,$A19) -> 26 | C19: =B19/SUM(B$5:B$28) -> 0.026 | D19: =COUNTIFS(d_hour,$A19,d_assigned,FALSE()) -> 1 | E19: =IFERROR(D19/B19,0) -> 0.038461538 | F19: =COUNTIFS(d_hour,$A19,d_status,"Cancelled*") -> 3 | G19: =IFERROR(F19/B19,0) -> 0.11538462 | H19: =IFERROR(AVERAGEIFS(d_tat,d_hour,$A19),0) -> 41.391304
A20: 15 | B20: =COUNTIFS(d_hour,$A20) -> 39 | C20: =B20/SUM(B$5:B$28) -> 0.039 | D20: =COUNTIFS(d_hour,$A20,d_assigned,FALSE()) -> 3 | E20: =IFERROR(D20/B20,0) -> 0.076923077 | F20: =COUNTIFS(d_hour,$A20,d_status,"Cancelled*") -> 4 | G20: =IFERROR(F20/B20,0) -> 0.1025641 | H20: =IFERROR(AVERAGEIFS(d_tat,d_hour,$A20),0) -> 35.942857 | K20: Unassigned rate: Zone × Time band
A21: 16 | B21: =COUNTIFS(d_hour,$A21) -> 69 | C21: =B21/SUM(B$5:B$28) -> 0.069 | D21: =COUNTIFS(d_hour,$A21,d_assigned,FALSE()) -> 2 | E21: =IFERROR(D21/B21,0) -> 0.028985507 | F21: =COUNTIFS(d_hour,$A21,d_status,"Cancelled*") -> 9 | G21: =IFERROR(F21/B21,0) -> 0.13043478 | H21: =IFERROR(AVERAGEIFS(d_tat,d_hour,$A21),0) -> 37.416667 | K21: Zone | L21: Night (00-05) | M21: Morning (06-11) | N21: Afternoon (12-16) | O21: Evening (17-20) | P21: Late (21-23)
A22: 17 | B22: =COUNTIFS(d_hour,$A22) -> 83 | C22: =B22/SUM(B$5:B$28) -> 0.083 | D22: =COUNTIFS(d_hour,$A22,d_assigned,FALSE()) -> 9 | E22: =IFERROR(D22/B22,0) -> 0.10843373 | F22: =COUNTIFS(d_hour,$A22,d_status,"Cancelled*") -> 13 | G22: =IFERROR(F22/B22,0) -> 0.15662651 | H22: =IFERROR(AVERAGEIFS(d_tat,d_hour,$A22),0) -> 38.085714 | K22: Zone East | L22: =IFERROR(COUNTIFS(d_zone,$K22,d_band,L$21,d_assigned,FALSE())/COUNTIFS(d_zone,$K22,d_band,L$21),0) -> 0.36666667 | M22: =IFERROR(COUNTIFS(d_zone,$K22,d_band,M$21,d_assigned,FALSE())/COUNTIFS(d_zone,$K22,d_band,M$21),0) -> 0.16666667 | N22: =IFERROR(COUNTIFS(d_zone,$K22,d_band,N$21,d_assigned,FALSE())/COUNTIFS(d_zone,$K22,d_band,N$21),0) -> 0.063829787 | O22: =IFERROR(COUNTIFS(d_zone,$K22,d_band,O$21,d_assigned,FALSE())/COUNTIFS(d_zone,$K22,d_band,O$21),0) -> 0.04109589 | P22: =IFERROR(COUNTIFS(d_zone,$K22,d_band,P$21,d_assigned,FALSE())/COUNTIFS(d_zone,$K22,d_band,P$21),0) -> 0.027027027
A23: 18 | B23: =COUNTIFS(d_hour,$A23) -> 63 | C23: =B23/SUM(B$5:B$28) -> 0.063 | D23: =COUNTIFS(d_hour,$A23,d_assigned,FALSE()) -> 1 | E23: =IFERROR(D23/B23,0) -> 0.015873016 | F23: =COUNTIFS(d_hour,$A23,d_status,"Cancelled*") -> 3 | G23: =IFERROR(F23/B23,0) -> 0.047619048 | H23: =IFERROR(AVERAGEIFS(d_tat,d_hour,$A23),0) -> 36.616667 | K23: Zone North | L23: =IFERROR(COUNTIFS(d_zone,$K23,d_band,L$21,d_assigned,FALSE())/COUNTIFS(d_zone,$K23,d_band,L$21),0) -> 0.059405941 | M23: =IFERROR(COUNTIFS(d_zone,$K23,d_band,M$21,d_assigned,FALSE())/COUNTIFS(d_zone,$K23,d_band,M$21),0) -> 0.071428571 | N23: =IFERROR(COUNTIFS(d_zone,$K23,d_band,N$21,d_assigned,FALSE())/COUNTIFS(d_zone,$K23,d_band,N$21),0) -> 0.025 | O23: =IFERROR(COUNTIFS(d_zone,$K23,d_band,O$21,d_assigned,FALSE())/COUNTIFS(d_zone,$K23,d_band,O$21),0) -> 0.14035088 | P23: =IFERROR(COUNTIFS(d_zone,$K23,d_band,P$21,d_assigned,FALSE())/COUNTIFS(d_zone,$K23,d_band,P$21),0) -> 0
A24: 19 | B24: =COUNTIFS(d_hour,$A24) -> 52 | C24: =B24/SUM(B$5:B$28) -> 0.052 | D24: =COUNTIFS(d_hour,$A24,d_assigned,FALSE()) -> 3 | E24: =IFERROR(D24/B24,0) -> 0.057692308 | F24: =COUNTIFS(d_hour,$A24,d_status,"Cancelled*") -> 8 | G24: =IFERROR(F24/B24,0) -> 0.15384615 | H24: =IFERROR(AVERAGEIFS(d_tat,d_hour,$A24),0) -> 37.5 | K24: Zone South | L24: =IFERROR(COUNTIFS(d_zone,$K24,d_band,L$21,d_assigned,FALSE())/COUNTIFS(d_zone,$K24,d_band,L$21),0) -> 0.065934066 | M24: =IFERROR(COUNTIFS(d_zone,$K24,d_band,M$21,d_assigned,FALSE())/COUNTIFS(d_zone,$K24,d_band,M$21),0) -> 0.083333333 | N24: =IFERROR(COUNTIFS(d_zone,$K24,d_band,N$21,d_assigned,FALSE())/COUNTIFS(d_zone,$K24,d_band,N$21),0) -> 0.025 | O24: =IFERROR(COUNTIFS(d_zone,$K24,d_band,O$21,d_assigned,FALSE())/COUNTIFS(d_zone,$K24,d_band,O$21),0) -> 0.021276596 | P24: =IFERROR(COUNTIFS(d_zone,$K24,d_band,P$21,d_assigned,FALSE())/COUNTIFS(d_zone,$K24,d_band,P$21),0) -> 0.048780488
A25: 20 | B25: =COUNTIFS(d_hour,$A25) -> 39 | C25: =B25/SUM(B$5:B$28) -> 0.039 | D25: =COUNTIFS(d_hour,$A25,d_assigned,FALSE()) -> 4 | E25: =IFERROR(D25/B25,0) -> 0.1025641 | F25: =COUNTIFS(d_hour,$A25,d_status,"Cancelled*") -> 9 | G25: =IFERROR(F25/B25,0) -> 0.23076923 | H25: =IFERROR(AVERAGEIFS(d_tat,d_hour,$A25),0) -> 33.9 | K25: Zone West | L25: =IFERROR(COUNTIFS(d_zone,$K25,d_band,L$21,d_assigned,FALSE())/COUNTIFS(d_zone,$K25,d_band,L$21),0) -> 0.029411765 | M25: =IFERROR(COUNTIFS(d_zone,$K25,d_band,M$21,d_assigned,FALSE())/COUNTIFS(d_zone,$K25,d_band,M$21),0) -> 0.037037037 | N25: =IFERROR(COUNTIFS(d_zone,$K25,d_band,N$21,d_assigned,FALSE())/COUNTIFS(d_zone,$K25,d_band,N$21),0) -> 0.054054054 | O25: =IFERROR(COUNTIFS(d_zone,$K25,d_band,O$21,d_assigned,FALSE())/COUNTIFS(d_zone,$K25,d_band,O$21),0) -> 0.083333333 | P25: =IFERROR(COUNTIFS(d_zone,$K25,d_band,P$21,d_assigned,FALSE())/COUNTIFS(d_zone,$K25,d_band,P$21),0) -> 0.088235294
A26: 21 | B26: =COUNTIFS(d_hour,$A26) -> 54 | C26: =B26/SUM(B$5:B$28) -> 0.054 | D26: =COUNTIFS(d_hour,$A26,d_assigned,FALSE()) -> 2 | E26: =IFERROR(D26/B26,0) -> 0.037037037 | F26: =COUNTIFS(d_hour,$A26,d_status,"Cancelled*") -> 4 | G26: =IFERROR(F26/B26,0) -> 0.074074074 | H26: =IFERROR(AVERAGEIFS(d_tat,d_hour,$A26),0) -> 36.64
A27: 22 | B27: =COUNTIFS(d_hour,$A27) -> 49 | C27: =B27/SUM(B$5:B$28) -> 0.049 | D27: =COUNTIFS(d_hour,$A27,d_assigned,FALSE()) -> 2 | E27: =IFERROR(D27/B27,0) -> 0.040816327 | F27: =COUNTIFS(d_hour,$A27,d_status,"Cancelled*") -> 5 | G27: =IFERROR(F27/B27,0) -> 0.10204082 | H27: =IFERROR(AVERAGEIFS(d_tat,d_hour,$A27),0) -> 41.409091
A28: 23 | B28: =COUNTIFS(d_hour,$A28) -> 47 | C28: =B28/SUM(B$5:B$28) -> 0.047 | D28: =COUNTIFS(d_hour,$A28,d_assigned,FALSE()) -> 2 | E28: =IFERROR(D28/B28,0) -> 0.042553191 | F28: =COUNTIFS(d_hour,$A28,d_status,"Cancelled*") -> 5 | G28: =IFERROR(F28/B28,0) -> 0.10638298 | H28: =IFERROR(AVERAGEIFS(d_tat,d_hour,$A28),0) -> 38.404762 | K28: Orders: Zone × Time band
K29: Zone | L29: Night (00-05) | M29: Morning (06-11) | N29: Afternoon (12-16) | O29: Evening (17-20) | P29: Late (21-23)
K30: Zone East | L30: =COUNTIFS(d_zone,$K30,d_band,L$29) -> 90 | M30: =COUNTIFS(d_zone,$K30,d_band,M$29) -> 12 | N30: =COUNTIFS(d_zone,$K30,d_band,N$29) -> 47 | O30: =COUNTIFS(d_zone,$K30,d_band,O$29) -> 73 | P30: =COUNTIFS(d_zone,$K30,d_band,P$29) -> 37
K31: Zone North | L31: =COUNTIFS(d_zone,$K31,d_band,L$29) -> 101 | M31: =COUNTIFS(d_zone,$K31,d_band,M$29) -> 14 | N31: =COUNTIFS(d_zone,$K31,d_band,N$29) -> 40 | O31: =COUNTIFS(d_zone,$K31,d_band,O$29) -> 57 | P31: =COUNTIFS(d_zone,$K31,d_band,P$29) -> 38
K32: Zone South | L32: =COUNTIFS(d_zone,$K32,d_band,L$29) -> 91 | M32: =COUNTIFS(d_zone,$K32,d_band,M$29) -> 12 | N32: =COUNTIFS(d_zone,$K32,d_band,N$29) -> 40 | O32: =COUNTIFS(d_zone,$K32,d_band,O$29) -> 47 | P32: =COUNTIFS(d_zone,$K32,d_band,P$29) -> 41
K33: Zone West | L33: =COUNTIFS(d_zone,$K33,d_band,L$29) -> 102 | M33: =COUNTIFS(d_zone,$K33,d_band,M$29) -> 27 | N33: =COUNTIFS(d_zone,$K33,d_band,N$29) -> 37 | O33: =COUNTIFS(d_zone,$K33,d_band,O$29) -> 60 | P33: =COUNTIFS(d_zone,$K33,d_band,P$29) -> 34
K36: SLA breach rate (of completed): Zone × Time band
K37: Zone | L37: Night (00-05) | M37: Morning (06-11) | N37: Afternoon (12-16) | O37: Evening (17-20) | P37: Late (21-23)
K38: Zone East | L38: =IFERROR(SUMIFS(d_sla,d_zone,$K38,d_band,L$37)/COUNTIFS(d_zone,$K38,d_band,L$37,d_status,"Completed"),0) -> 0.28571429 | M38: =IFERROR(SUMIFS(d_sla,d_zone,$K38,d_band,M$37)/COUNTIFS(d_zone,$K38,d_band,M$37,d_status,"Completed"),0) -> 0 | N38: =IFERROR(SUMIFS(d_sla,d_zone,$K38,d_band,N$37)/COUNTIFS(d_zone,$K38,d_band,N$37,d_status,"Completed"),0) -> 0 | O38: =IFERROR(SUMIFS(d_sla,d_zone,$K38,d_band,O$37)/COUNTIFS(d_zone,$K38,d_band,O$37,d_status,"Completed"),0) -> 0 | P38: =IFERROR(SUMIFS(d_sla,d_zone,$K38,d_band,P$37)/COUNTIFS(d_zone,$K38,d_band,P$37,d_status,"Completed"),0) -> 0
K39: Zone North | L39: =IFERROR(SUMIFS(d_sla,d_zone,$K39,d_band,L$37)/COUNTIFS(d_zone,$K39,d_band,L$37,d_status,"Completed"),0) -> 0 | M39: =IFERROR(SUMIFS(d_sla,d_zone,$K39,d_band,M$37)/COUNTIFS(d_zone,$K39,d_band,M$37,d_status,"Completed"),0) -> 0 | N39: =IFERROR(SUMIFS(d_sla,d_zone,$K39,d_band,N$37)/COUNTIFS(d_zone,$K39,d_band,N$37,d_status,"Completed"),0) -> 0 | O39: =IFERROR(SUMIFS(d_sla,d_zone,$K39,d_band,O$37)/COUNTIFS(d_zone,$K39,d_band,O$37,d_status,"Completed"),0) -> 0 | P39: =IFERROR(SUMIFS(d_sla,d_zone,$K39,d_band,P$37)/COUNTIFS(d_zone,$K39,d_band,P$37,d_status,"Completed"),0) -> 0
K40: Zone South | L40: =IFERROR(SUMIFS(d_sla,d_zone,$K40,d_band,L$37)/COUNTIFS(d_zone,$K40,d_band,L$37,d_status,"Completed"),0) -> 0 | M40: =IFERROR(SUMIFS(d_sla,d_zone,$K40,d_band,M$37)/COUNTIFS(d_zone,$K40,d_band,M$37,d_status,"Completed"),0) -> 0 | N40: =IFERROR(SUMIFS(d_sla,d_zone,$K40,d_band,N$37)/COUNTIFS(d_zone,$K40,d_band,N$37,d_status,"Completed"),0) -> 0 | O40: =IFERROR(SUMIFS(d_sla,d_zone,$K40,d_band,O$37)/COUNTIFS(d_zone,$K40,d_band,O$37,d_status,"Completed"),0) -> 0 | P40: =IFERROR(SUMIFS(d_sla,d_zone,$K40,d_band,P$37)/COUNTIFS(d_zone,$K40,d_band,P$37,d_status,"Completed"),0) -> 0
K41: Zone West | L41: =IFERROR(SUMIFS(d_sla,d_zone,$K41,d_band,L$37)/COUNTIFS(d_zone,$K41,d_band,L$37,d_status,"Completed"),0) -> 0 | M41: =IFERROR(SUMIFS(d_sla,d_zone,$K41,d_band,M$37)/COUNTIFS(d_zone,$K41,d_band,M$37,d_status,"Completed"),0) -> 0 | N41: =IFERROR(SUMIFS(d_sla,d_zone,$K41,d_band,N$37)/COUNTIFS(d_zone,$K41,d_band,N$37,d_status,"Completed"),0) -> 0 | O41: =IFERROR(SUMIFS(d_sla,d_zone,$K41,d_band,O$37)/COUNTIFS(d_zone,$K41,d_band,O$37,d_status,"Completed"),0) -> 0 | P41: =IFERROR(SUMIFS(d_sla,d_zone,$K41,d_band,P$37)/COUNTIFS(d_zone,$K41,d_band,P$37,d_status,"Completed"),0) -> 0

Sheet Daily
A1: Daily demand velocity
A2: Orders per day by category, day-over-day change and 3-day moving average
A4: Date | B4: Appliance Repair | C4: Home Cleaning | D4: Plumbing | E4: Salon Services | F4: Total orders | G4: DoD change | H4: 3-day moving avg | I4: Unassigned % | J4: Cancellation %
A5: 46315 | B5: =COUNTIFS(d_date,$A5,d_cat,B$4) -> 20 | C5: =COUNTIFS(d_date,$A5,d_cat,C$4) -> 20 | D5: =COUNTIFS(d_date,$A5,d_cat,D$4) -> 21 | E5: =COUNTIFS(d_date,$A5,d_cat,E$4) -> 17 | F5: =SUM(B5:E5) -> 78 | H5: =AVERAGE(F5:F5) -> 78 | I5: =IFERROR(COUNTIFS(d_date,$A5,d_assigned,FALSE())/F5,0) -> 0.038461538 | J5: =IFERROR(COUNTIFS(d_date,$A5,d_status,"Cancelled*")/F5,0) -> 0.076923077
A6: 46316 | B6: =COUNTIFS(d_date,$A6,d_cat,B$4) -> 29 | C6: =COUNTIFS(d_date,$A6,d_cat,C$4) -> 31 | D6: =COUNTIFS(d_date,$A6,d_cat,D$4) -> 43 | E6: =COUNTIFS(d_date,$A6,d_cat,E$4) -> 41 | F6: =SUM(B6:E6) -> 144 | G6: =IFERROR(F6/F5-1,"") -> 0.84615385 | H6: =AVERAGE(F5:F6) -> 111 | I6: =IFERROR(COUNTIFS(d_date,$A6,d_assigned,FALSE())/F6,0) -> 0.090277778 | J6: =IFERROR(COUNTIFS(d_date,$A6,d_status,"Cancelled*")/F6,0) -> 0.10416667
A7: 46317 | B7: =COUNTIFS(d_date,$A7,d_cat,B$4) -> 26 | C7: =COUNTIFS(d_date,$A7,d_cat,C$4) -> 40 | D7: =COUNTIFS(d_date,$A7,d_cat,D$4) -> 30 | E7: =COUNTIFS(d_date,$A7,d_cat,E$4) -> 37 | F7: =SUM(B7:E7) -> 133 | G7: =IFERROR(F7/F6-1,"") -> -0.076388889 | H7: =AVERAGE(F5:F7) -> 118.33333 | I7: =IFERROR(COUNTIFS(d_date,$A7,d_assigned,FALSE())/F7,0) -> 0.082706767 | J7: =IFERROR(COUNTIFS(d_date,$A7,d_status,"Cancelled*")/F7,0) -> 0.12030075
A8: 46318 | B8: =COUNTIFS(d_date,$A8,d_cat,B$4) -> 34 | C8: =COUNTIFS(d_date,$A8,d_cat,C$4) -> 35 | D8: =COUNTIFS(d_date,$A8,d_cat,D$4) -> 37 | E8: =COUNTIFS(d_date,$A8,d_cat,E$4) -> 37 | F8: =SUM(B8:E8) -> 143 | G8: =IFERROR(F8/F7-1,"") -> 0.07518797 | H8: =AVERAGE(F6:F8) -> 140 | I8: =IFERROR(COUNTIFS(d_date,$A8,d_assigned,FALSE())/F8,0) -> 0.090909091 | J8: =IFERROR(COUNTIFS(d_date,$A8,d_status,"Cancelled*")/F8,0) -> 0.13286713
A9: 46319 | B9: =COUNTIFS(d_date,$A9,d_cat,B$4) -> 24 | C9: =COUNTIFS(d_date,$A9,d_cat,C$4) -> 41 | D9: =COUNTIFS(d_date,$A9,d_cat,D$4) -> 35 | E9: =COUNTIFS(d_date,$A9,d_cat,E$4) -> 42 | F9: =SUM(B9:E9) -> 142 | G9: =IFERROR(F9/F8-1,"") -> -0.006993007 | H9: =AVERAGE(F7:F9) -> 139.33333 | I9: =IFERROR(COUNTIFS(d_date,$A9,d_assigned,FALSE())/F9,0) -> 0.098591549 | J9: =IFERROR(COUNTIFS(d_date,$A9,d_status,"Cancelled*")/F9,0) -> 0.16197183
A10: 46320 | B10: =COUNTIFS(d_date,$A10,d_cat,B$4) -> 41 | C10: =COUNTIFS(d_date,$A10,d_cat,C$4) -> 30 | D10: =COUNTIFS(d_date,$A10,d_cat,D$4) -> 43 | E10: =COUNTIFS(d_date,$A10,d_cat,E$4) -> 40 | F10: =SUM(B10:E10) -> 154 | G10: =IFERROR(F10/F9-1,"") -> 0.084507042 | H10: =AVERAGE(F8:F10) -> 146.33333 | I10: =IFERROR(COUNTIFS(d_date,$A10,d_assigned,FALSE())/F10,0) -> 0.077922078 | J10: =IFERROR(COUNTIFS(d_date,$A10,d_status,"Cancelled*")/F10,0) -> 0.18181818
A11: 46321 | B11: =COUNTIFS(d_date,$A11,d_cat,B$4) -> 37 | C11: =COUNTIFS(d_date,$A11,d_cat,C$4) -> 41 | D11: =COUNTIFS(d_date,$A11,d_cat,D$4) -> 34 | E11: =COUNTIFS(d_date,$A11,d_cat,E$4) -> 29 | F11: =SUM(B11:E11) -> 141 | G11: =IFERROR(F11/F10-1,"") -> -0.084415584 | H11: =AVERAGE(F9:F11) -> 145.66667 | I11: =IFERROR(COUNTIFS(d_date,$A11,d_assigned,FALSE())/F11,0) -> 0.09929078 | J11: =IFERROR(COUNTIFS(d_date,$A11,d_status,"Cancelled*")/F11,0) -> 0.12765957
A12: 46322 | B12: =COUNTIFS(d_date,$A12,d_cat,B$4) -> 15 | C12: =COUNTIFS(d_date,$A12,d_cat,C$4) -> 17 | D12: =COUNTIFS(d_date,$A12,d_cat,D$4) -> 16 | E12: =COUNTIFS(d_date,$A12,d_cat,E$4) -> 17 | F12: =SUM(B12:E12) -> 65 | G12: =IFERROR(F12/F11-1,"") -> -0.53900709 | H12: =AVERAGE(F10:F12) -> 120 | I12: =IFERROR(COUNTIFS(d_date,$A12,d_assigned,FALSE())/F12,0) -> 0.046153846 | J12: =IFERROR(COUNTIFS(d_date,$A12,d_status,"Cancelled*")/F12,0) -> 0.16923077
A14: Note: 20 Oct and 27 Oct have far fewer orders than the other days (likely partial days at the edges of the export window), so their day-over-day swings are not real demand changes.

Sheet Alerts
A1: Operational alerts
A2: Severity recalculates when thresholds (yellow cells) or data change
A3: Alert thresholds (edit) | D3: Alert count
A4: Unassigned % – WARNING | B4: 0.1 | D4: CRITICAL | E4: =COUNTIF(F13:F32,"CRITICAL")+COUNTIF(F37:F56,"CRITICAL")+COUNTIF(D61:D64,"CRITICAL")+COUNTIF(F61:F64,"CRITICAL") -> 4
A5: Unassigned % – CRITICAL | B5: 0.15 | D5: WARNING | E5: =COUNTIF(F13:F32,"WARNING")+COUNTIF(F37:F56,"WARNING")+COUNTIF(D61:D64,"WARNING")+COUNTIF(F61:F64,"WARNING") -> 5
A6: SLA breach % – WARNING | B6: 0.03
A7: SLA breach % – CRITICAL | B7: 0.05
A8: Minimum orders in a cell | B8: 20
A11: 1 · Supply shortage — Category × Time band
A12: Service category | B12: Time band | C12: Orders | D12: No-partner orders | E12: Unassigned % | F12: Severity
A13: Appliance Repair | B13: Night (00-05) | C13: =COUNTIFS(d_cat,$A13,d_band,$B13) -> 88 | D13: =COUNTIFS(d_cat,$A13,d_band,$B13,d_assigned,FALSE()) -> 9 | E13: =IFERROR(D13/C13,0) -> 0.10227273 | F13: =IF(C13<$B$8,"LOW VOLUME",IF(E13>=$B$5,"CRITICAL",IF(E13>=$B$4,"WARNING","OK"))) -> WARNING
A14: Appliance Repair | B14: Morning (06-11) | C14: =COUNTIFS(d_cat,$A14,d_band,$B14) -> 14 | D14: =COUNTIFS(d_cat,$A14,d_band,$B14,d_assigned,FALSE()) -> 1 | E14: =IFERROR(D14/C14,0) -> 0.071428571 | F14: =IF(C14<$B$8,"LOW VOLUME",IF(E14>=$B$5,"CRITICAL",IF(E14>=$B$4,"WARNING","OK"))) -> LOW VOLUME
A15: Appliance Repair | B15: Afternoon (12-16) | C15: =COUNTIFS(d_cat,$A15,d_band,$B15) -> 45 | D15: =COUNTIFS(d_cat,$A15,d_band,$B15,d_assigned,FALSE()) -> 4 | E15: =IFERROR(D15/C15,0) -> 0.088888889 | F15: =IF(C15<$B$8,"LOW VOLUME",IF(E15>=$B$5,"CRITICAL",IF(E15>=$B$4,"WARNING","OK"))) -> OK
A16: Appliance Repair | B16: Evening (17-20) | C16: =COUNTIFS(d_cat,$A16,d_band,$B16) -> 53 | D16: =COUNTIFS(d_cat,$A16,d_band,$B16,d_assigned,FALSE()) -> 3 | E16: =IFERROR(D16/C16,0) -> 0.056603774 | F16: =IF(C16<$B$8,"LOW VOLUME",IF(E16>=$B$5,"CRITICAL",IF(E16>=$B$4,"WARNING","OK"))) -> OK
A17: Appliance Repair | B17: Late (21-23) | C17: =COUNTIFS(d_cat,$A17,d_band,$B17) -> 26 | D17: =COUNTIFS(d_cat,$A17,d_band,$B17,d_assigned,FALSE()) -> 2 | E17: =IFERROR(D17/C17,0) -> 0.076923077 | F17: =IF(C17<$B$8,"LOW VOLUME",IF(E17>=$B$5,"CRITICAL",IF(E17>=$B$4,"WARNING","OK"))) -> OK
A18: Home Cleaning | B18: Night (00-05) | C18: =COUNTIFS(d_cat,$A18,d_band,$B18) -> 93 | D18: =COUNTIFS(d_cat,$A18,d_band,$B18,d_assigned,FALSE()) -> 15 | E18: =IFERROR(D18/C18,0) -> 0.16129032 | F18: =IF(C18<$B$8,"LOW VOLUME",IF(E18>=$B$5,"CRITICAL",IF(E18>=$B$4,"WARNING","OK"))) -> CRITICAL
A19: Home Cleaning | B19: Morning (06-11) | C19: =COUNTIFS(d_cat,$A19,d_band,$B19) -> 17 | D19: =COUNTIFS(d_cat,$A19,d_band,$B19,d_assigned,FALSE()) -> 2 | E19: =IFERROR(D19/C19,0) -> 0.11764706 | F19: =IF(C19<$B$8,"LOW VOLUME",IF(E19>=$B$5,"CRITICAL",IF(E19>=$B$4,"WARNING","OK"))) -> LOW VOLUME
A20: Home Cleaning | B20: Afternoon (12-16) | C20: =COUNTIFS(d_cat,$A20,d_band,$B20) -> 44 | D20: =COUNTIFS(d_cat,$A20,d_band,$B20,d_assigned,FALSE()) -> 1 | E20: =IFERROR(D20/C20,0) -> 0.022727273 | F20: =IF(C20<$B$8,"LOW VOLUME",IF(E20>=$B$5,"CRITICAL",IF(E20>=$B$4,"WARNING","OK"))) -> OK
A21: Home Cleaning | B21: Evening (17-20) | C21: =COUNTIFS(d_cat,$A21,d_band,$B21) -> 55 | D21: =COUNTIFS(d_cat,$A21,d_band,$B21,d_assigned,FALSE()) -> 3 | E21: =IFERROR(D21/C21,0) -> 0.054545455 | F21: =IF(C21<$B$8,"LOW VOLUME",IF(E21>=$B$5,"CRITICAL",IF(E21>=$B$4,"WARNING","OK"))) -> OK
A22: Home Cleaning | B22: Late (21-23) | C22: =COUNTIFS(d_cat,$A22,d_band,$B22) -> 46 | D22: =COUNTIFS(d_cat,$A22,d_band,$B22,d_assigned,FALSE()) -> 2 | E22: =IFERROR(D22/C22,0) -> 0.043478261 | F22: =IF(C22<$B$8,"LOW VOLUME",IF(E22>=$B$5,"CRITICAL",IF(E22>=$B$4,"WARNING","OK"))) -> OK
A23: Plumbing | B23: Night (00-05) | C23: =COUNTIFS(d_cat,$A23,d_band,$B23) -> 95 | D23: =COUNTIFS(d_cat,$A23,d_band,$B23,d_assigned,FALSE()) -> 10 | E23: =IFERROR(D23/C23,0) -> 0.10526316 | F23: =IF(C23<$B$8,"LOW VOLUME",IF(E23>=$B$5,"CRITICAL",IF(E23>=$B$4,"WARNING","OK"))) -> WARNING
A24: Plumbing | B24: Morning (06-11) | C24: =COUNTIFS(d_cat,$A24,d_band,$B24) -> 18 | D24: =COUNTIFS(d_cat,$A24,d_band,$B24,d_assigned,FALSE()) -> 0 | E24: =IFERROR(D24/C24,0) -> 0 | F24: =IF(C24<$B$8,"LOW VOLUME",IF(E24>=$B$5,"CRITICAL",IF(E24>=$B$4,"WARNING","OK"))) -> LOW VOLUME
... A32: Salon Services | B32: Late (21-23) | C32: =COUNTIFS(d_cat,$A32,d_band,$B32) -> 44 | D32: =COUNTIFS(d_cat,$A32,d_band,$B32,d_assigned,FALSE()) -> 1 | E32: =IFERROR(D32/C32,0) -> 0.022727273 | F32: =IF(C32<$B$8,"LOW VOLUME",IF(E32>=$B$5,"CRITICAL",IF(E32>=$B$4,"WARNING","OK"))) -> OK
A35: 2 · Partner coverage gap — Zone × Time band (where + when)
A36: City zone | B36: Time band | C36: Orders | D36: No-partner orders | E36: Unassigned % | F36: Severity
A37: Zone East | B37: Night (00-05) | C37: =COUNTIFS(d_zone,$A37,d_band,$B37) -> 90 | D37: =COUNTIFS(d_zone,$A37,d_band,$B37,d_assigned,FALSE()) -> 33 | E37: =IFERROR(D37/C37,0) -> 0.36666667 | F37: =IF(C37<$B$8,"LOW VOLUME",IF(E37>=$B$5,"CRITICAL",IF(E37>=$B$4,"WARNING","OK"))) -> CRITICAL
A38: Zone East | B38: Morning (06-11) | C38: =COUNTIFS(d_zone,$A38,d_band,$B38) -> 12 | D38: =COUNTIFS(d_zone,$A38,d_band,$B38,d_assigned,FALSE()) -> 2 | E38: =IFERROR(D38/C38,0) -> 0.16666667 | F38: =IF(C38<$B$8,"LOW VOLUME",IF(E38>=$B$5,"CRITICAL",IF(E38>=$B$4,"WARNING","OK"))) -> LOW VOLUME
A39: Zone East | B39: Afternoon (12-16) | C39: =COUNTIFS(d_zone,$A39,d_band,$B39) -> 47 | D39: =COUNTIFS(d_zone,$A39,d_band,$B39,d_assigned,FALSE()) -> 3 | E39: =IFERROR(D39/C39,0) -> 0.063829787 | F39: =IF(C39<$B$8,"LOW VOLUME",IF(E39>=$B$5,"CRITICAL",IF(E39>=$B$4,"WARNING","OK"))) -> OK
A40: Zone East | B40: Evening (17-20) | C40: =COUNTIFS(d_zone,$A40,d_band,$B40) -> 73 | D40: =COUNTIFS(d_zone,$A40,d_band,$B40,d_assigned,FALSE()) -> 3 | E40: =IFERROR(D40/C40,0) -> 0.04109589 | F40: =IF(C40<$B$8,"LOW VOLUME",IF(E40>=$B$5,"CRITICAL",IF(E40>=$B$4,"WARNING","OK"))) -> OK
A41: Zone East | B41: Late (21-23) | C41: =COUNTIFS(d_zone,$A41,d_band,$B41) -> 37 | D41: =COUNTIFS(d_zone,$A41,d_band,$B41,d_assigned,FALSE()) -> 1 | E41: =IFERROR(D41/C41,0) -> 0.027027027 | F41: =IF(C41<$B$8,"LOW VOLUME",IF(E41>=$B$5,"CRITICAL",IF(E41>=$B$4,"WARNING","OK"))) -> OK
A42: Zone North | B42: Night (00-05) | C42: =COUNTIFS(d_zone,$A42,d_band,$B42) -> 101 | D42: =COUNTIFS(d_zone,$A42,d_band,$B42,d_assigned,FALSE()) -> 6 | E42: =IFERROR(D42/C42,0) -> 0.059405941 | F42: =IF(C42<$B$8,"LOW VOLUME",IF(E42>=$B$5,"CRITICAL",IF(E42>=$B$4,"WARNING","OK"))) -> OK
A43: Zone North | B43: Morning (06-11) | C43: =COUNTIFS(d_zone,$A43,d_band,$B43) -> 14 | D43: =COUNTIFS(d_zone,$A43,d_band,$B43,d_assigned,FALSE()) -> 1 | E43: =IFERROR(D43/C43,0) -> 0.071428571 | F43: =IF(C43<$B$8,"LOW VOLUME",IF(E43>=$B$5,"CRITICAL",IF(E43>=$B$4,"WARNING","OK"))) -> LOW VOLUME
A44: Zone North | B44: Afternoon (12-16) | C44: =COUNTIFS(d_zone,$A44,d_band,$B44) -> 40 | D44: =COUNTIFS(d_zone,$A44,d_band,$B44,d_assigned,FALSE()) -> 1 | E44: =IFERROR(D44/C44,0) -> 0.025 | F44: =IF(C44<$B$8,"LOW VOLUME",IF(E44>=$B$5,"CRITICAL",IF(E44>=$B$4,"WARNING","OK"))) -> OK
A45: Zone North | B45: Evening (17-20) | C45: =COUNTIFS(d_zone,$A45,d_band,$B45) -> 57 | D45: =COUNTIFS(d_zone,$A45,d_band,$B45,d_assigned,FALSE()) -> 8 | E45: =IFERROR(D45/C45,0) -> 0.14035088 | F45: =IF(C45<$B$8,"LOW VOLUME",IF(E45>=$B$5,"CRITICAL",IF(E45>=$B$4,"WARNING","OK"))) -> WARNING
A46: Zone North | B46: Late (21-23) | C46: =COUNTIFS(d_zone,$A46,d_band,$B46) -> 38 | D46: =COUNTIFS(d_zone,$A46,d_band,$B46,d_assigned,FALSE()) -> 0 | E46: =IFERROR(D46/C46,0) -> 0 | F46: =IF(C46<$B$8,"LOW VOLUME",IF(E46>=$B$5,"CRITICAL",IF(E46>=$B$4,"WARNING","OK"))) -> OK
A47: Zone South | B47: Night (00-05) | C47: =COUNTIFS(d_zone,$A47,d_band,$B47) -> 91 | D47: =COUNTIFS(d_zone,$A47,d_band,$B47,d_assigned,FALSE()) -> 6 | E47: =IFERROR(D47/C47,0) -> 0.065934066 | F47: =IF(C47<$B$8,"LOW VOLUME",IF(E47>=$B$5,"CRITICAL",IF(E47>=$B$4,"WARNING","OK"))) -> OK
A48: Zone South | B48: Morning (06-11) | C48: =COUNTIFS(d_zone,$A48,d_band,$B48) -> 12 | D48: =COUNTIFS(d_zone,$A48,d_band,$B48,d_assigned,FALSE()) -> 1 | E48: =IFERROR(D48/C48,0) -> 0.083333333 | F48: =IF(C48<$B$8,"LOW VOLUME",IF(E48>=$B$5,"CRITICAL",IF(E48>=$B$4,"WARNING","OK"))) -> LOW VOLUME
... A56: Zone West | B56: Late (21-23) | C56: =COUNTIFS(d_zone,$A56,d_band,$B56) -> 34 | D56: =COUNTIFS(d_zone,$A56,d_band,$B56,d_assigned,FALSE()) -> 3 | E56: =IFERROR(D56/C56,0) -> 0.088235294 | F56: =IF(C56<$B$8,"LOW VOLUME",IF(E56>=$B$5,"CRITICAL",IF(E56>=$B$4,"WARNING","OK"))) -> OK
A59: 3 · Zone health
A60: City zone | B60: Orders | C60: Unassigned % | D60: Coverage severity | E60: SLA breach % (completed) | F60: SLA severity
...

Sheet Data
A1: order_id | B1: order_date | C1: order_hour | D1: service_category | E1: city_zone | F1: order_status | G1: partner_assigned | H1: order_value | I1: customer_rating | J1: tat_minutes | K1: is_sla_breach | L1: time_band
A2: ORD_10001 | B2: 46320 | C2: 15 | D2: Appliance Repair | E2: Zone South | F2: Completed | G2: =TRUE() -> TRUE | H2: 468.77 | I2: 3 | J2: 54 | K2: 0 | L2: =IF(C2="","",IF(C2<=5,"Night (00-05)",IF(C2<=11,"Morning (06-11)",IF(C2<=16,"Afternoon (12-16)",IF(C2<=20,"Evening (17-20)","Late (21-23)"))))) -> Afternoon (12-16)
A3: ORD_10002 | B3: 46318 | C3: 11 | D3: Appliance Repair | E3: Zone North | F3: Completed | G3: =TRUE() -> TRUE | H3: 679.62 | I3: 4 | J3: 54 | K3: 0 | L3: =IF(C3="","",IF(C3<=5,"Night (00-05)",IF(C3<=11,"Morning (06-11)",IF(C3<=16,"Afternoon (12-16)",IF(C3<=20,"Evening (17-20)","Late (21-23)"))))) -> Morning (06-11)
A4: ORD_10003 | B4: 46318 | C4: 23 | D4: Home Cleaning | E4: Zone South | F4: Completed | G4: =TRUE() -> TRUE | H4: 1287.7 | I4: 4 | J4: 29 | K4: 0 | L4: =IF(C4="","",IF(C4<=5,"Night (00-05)",IF(C4<=11,"Morning (06-11)",IF(C4<=16,"Afternoon (12-16)",IF(C4<=20,"Evening (17-20)","Late (21-23)"))))) -> Late (21-23)
A5: ORD_10004 | B5: 46321 | C5: 18 | D5: Home Cleaning | E5: Zone East | F5: Completed | G5: =TRUE() -> TRUE | H5: 1392.25 | I5: 5 | J5: 22 | K5: 0 | L5: =IF(C5="","",IF(C5<=5,"Night (00-05)",IF(C5<=11,"Morning (06-11)",IF(C5<=16,"Afternoon (12-16)",IF(C5<=20,"Evening (17-20)","Late (21-23)"))))) -> Evening (17-20)
A6: ORD_10005 | B6: 46319 | C6: 15 | D6: Home Cleaning | E6: Zone East | F6: Completed | G6: =TRUE() -> TRUE | H6: 1379.58 | I6: 5 | J6: 43 | K6: 0 | L6: =IF(C6="","",IF(C6<=5,"Night (00-05)",IF(C6<=11,"Morning (06-11)",IF(C6<=16,"Afternoon (12-16)",IF(C6<=20,"Evening (17-20)","Late (21-23)"))))) -> Afternoon (12-16)
A7: ORD_10006 | B7: 46320 | C7: 14 | D7: Salon Services | E7: Zone North | F7: Completed | G7: =TRUE() -> TRUE | H7: 1183.25 | I7: 4 | J7: 44 | K7: 0 | L7: =IF(C7="","",IF(C7<=5,"Night (00-05)",IF(C7<=11,"Morning (06-11)",IF(C7<=16,"Afternoon (12-16)",IF(C7<=20,"Evening (17-20)","Late (21-23)"))))) -> Afternoon (12-16)
A8: ORD_10007 | B8: 46321 | C8: 2 | D8: Salon Services | E8: Zone South | F8: Completed | G8: =TRUE() -> TRUE | H8: 1035.14 | I8: 5 | J8: 24 | K8: 0 | L8: =IF(C8="","",IF(C8<=5,"Night (00-05)",IF(C8<=11,"Morning (06-11)",IF(C8<=16,"Afternoon (12-16)",IF(C8<=20,"Evening (17-20)","Late (21-23)"))))) -> Night (00-05)
A9: ORD_10008 | B9: 46316 | C9: 22 | D9: Plumbing | E9: Zone West | F9: Cancelled_Customer | G9: =TRUE() -> TRUE | H9: 406.98 | K9: 0 | L9: =IF(C9="","",IF(C9<=5,"Night (00-05)",IF(C9<=11,"Morning (06-11)",IF(C9<=16,"Afternoon (12-16)",IF(C9<=20,"Evening (17-20)","Late (21-23)"))))) -> Late (21-23)
A10: ORD_10009 | B10: 46320 | C10: 23 | D10: Home Cleaning | E10: Zone South | F10: Completed | G10: =TRUE() -> TRUE | H10: 1374.26 | I10: 4 | J10: 45 | K10: 0 | L10: =IF(C10="","",IF(C10<=5,"Night (00-05)",IF(C10<=11,"Morning (06-11)",IF(C10<=16,"Afternoon (12-16)",IF(C10<=20,"Evening (17-20)","Late (21-23)"))))) -> Late (21-23)
A11: ORD_10010 | B11: 46317 | C11: 4 | D11: Salon Services | E11: Zone South | F11: Completed | G11: =TRUE() -> TRUE | H11: 1023.35 | I11: 3 | J11: 49 | K11: 0 | L11: =IF(C11="","",IF(C11<=5,"Night (00-05)",IF(C11<=11,"Morning (06-11)",IF(C11<=16,"Afternoon (12-16)",IF(C11<=20,"Evening (17-20)","Late (21-23)"))))) -> Night (00-05)
A12: ORD_10011 | B12: 46316 | C12: 17 | D12: Salon Services | E12: Zone West | F12: Completed | G12: =TRUE() -> TRUE | H12: 1217.26 | I12: 5 | J12: 34 | K12: 0 | L12: =IF(C12="","",IF(C12<=5,"Night (00-05)",IF(C12<=11,"Morning (06-11)",IF(C12<=16,"Afternoon (12-16)",IF(C12<=20,"Evening (17-20)","Late (21-23)"))))) -> Evening (17-20)
A13: ORD_10012 | B13: 46316 | C13: 22 | D13: Home Cleaning | E13: Zone North | F13: Completed | G13: =TRUE() -> TRUE | H13: 905.99 | I13: 5 | J13: 47 | K13: 0 | L13: =IF(C13="","",IF(C13<=5,"Night (00-05)",IF(C13<=11,"Morning (06-11)",IF(C13<=16,"Afternoon (12-16)",IF(C13<=20,"Evening (17-20)","Late (21-23)"))))) -> Late (21-23)
A14: ORD_10013 | B14: 46318 | C14: 19 | D14: Salon Services | E14: Zone North | F14: Completed | G14: =TRUE() -> TRUE | H14: 1043.23 | I14: 5 | J14: 54 | K14: 0 | L14: =IF(C14="","",IF(C14<=5,"Night (00-05)",IF(C14<=11,"Morning (06-11)",IF(C14<=16,"Afternoon (12-16)",IF(C14<=20,"Evening (17-20)","Late (21-23)"))))) -> Evening (17-20)
A15: ORD_10014 | B15: 46322 | C15: 0 | D15: Plumbing | E15: Zone South | F15: Cancelled_Customer | G15: =TRUE() -> TRUE | H15: 480.49 | K15: 0 | L15: =IF(C15="","",IF(C15<=5,"Night (00-05)",IF(C15<=11,"Morning (06-11)",IF(C15<=16,"Afternoon (12-16)",IF(C15<=20,"Evening (17-20)","Late (21-23)"))))) -> Night (00-05)
A16: ORD_10015 | B16: 46320 | C16: 17 | D16: Appliance Repair | E16: Zone North | F16: Completed | G16: =TRUE() -> TRUE | H16: 834.26 | I16: 5 | J16: 52 | K16: 0 | L16: =IF(C16="","",IF(C16<=5,"Night (00-05)",IF(C16<=11,"Morning (06-11)",IF(C16<=16,"Afternoon (12-16)",IF(C16<=20,"Evening (17-20)","Late (21-23)"))))) -> Evening (17-20)
A17: ORD_10016 | B17: 46316 | C17: 19 | D17: Home Cleaning | E17: Zone East | F17: Completed | G17: =TRUE() -> TRUE | H17: 1141.02 | I17: 5 | J17: 43 | K17: 0 | L17: =IF(C17="","",IF(C17<=5,"Night (00-05)",IF(C17<=11,"Morning (06-11)",IF(C17<=16,"Afternoon (12-16)",IF(C17<=20,"Evening (17-20)","Late (21-23)"))))) -> Evening (17-20)
A18: ORD_10017 | B18: 46322 | C18: 2 | D18: Appliance Repair | E18: Zone North | F18: Completed | G18: =TRUE() -> TRUE | H18: 441.83 | I18: 5 | J18: 24 | K18: 0 | L18: =IF(C18="","",IF(C18<=5,"Night (00-05)",IF(C18<=11,"Morning (06-11)",IF(C18<=16,"Afternoon (12-16)",IF(C18<=20,"Evening (17-20)","Late (21-23)"))))) -> Night (00-05)
A19: ORD_10018 | B19: 46320 | C19: 2 | D19: Plumbing | E19: Zone South | F19: Completed | G19: =TRUE() -> TRUE | H19: 405.02 | I19: 5 | J19: 47 | K19: 0 | L19: =IF(C19="","",IF(C19<=5,"Night (00-05)",IF(C19<=11,"Morning (06-11)",IF(C19<=16,"Afternoon (12-16)",IF(C19<=20,"Evening (17-20)","Late (21-23)"))))) -> Night (00-05)
A20: ORD_10019 | B20: 46320 | C20: 1 | D20: Salon Services | E20: Zone West | F20: Completed | G20: =TRUE() -> TRUE | H20: 1295.12 | I20: 5 | J20: 48 | K20: 0 | L20: =IF(C20="","",IF(C20<=5,"Night (00-05)",IF(C20<=11,"Morning (06-11)",IF(C20<=16,"Afternoon (12-16)",IF(C20<=20,"Evening (17-20)","Late (21-23)"))))) -> Night (00-05)
A21: ORD_10020 | B21: 46318 | C21: 15 | D21: Salon Services | E21: Zone North | F21: Completed | G21: =TRUE() -> TRUE | H21: 969.65 | I21: 1 | J21: 34 | K21: 0 | L21: =IF(C21="","",IF(C21<=5,"Night (00-05)",IF(C21<=11,"Morning (06-11)",IF(C21<=16,"Afternoon (12-16)",IF(C21<=20,"Evening (17-20)","Late (21-23)"))))) -> Afternoon (12-16)
A22: ORD_10021 | B22: 46321 | C22: 0 | D22: Home Cleaning | E22: Zone East | F22: Completed | G22: =TRUE() -> TRUE | H22: 848.6 | I22: 4 | J22: 51 | K22: 0 | L22: =IF(C22="","",IF(C22<=5,"Night (00-05)",IF(C22<=11,"Morning (06-11)",IF(C22<=16,"Afternoon (12-16)",IF(C22<=20,"Evening (17-20)","Late (21-23)"))))) -> Night (00-05)
A23: ORD_10022 | B23: 46317 | C23: 1 | D23: Plumbing | E23: Zone South | F23: Completed | G23: =TRUE() -> TRUE | H23: 612.85 | I23: 3 | J23: 32 | K23: 0 | L23: =IF(C23="","",IF(C23<=5,"Night (00-05)",IF(C23<=11,"Morning (06-11)",IF(C23<=16,"Afternoon (12-16)",IF(C23<=20,"Evening (17-20)","Late (21-23)"))))) -> Night (00-05)
A24: ORD_10023 | B24: 46320 | C24: 20 | D24: Plumbing | E24: Zone North | F24: Cancelled_Provider | G24: =FALSE() -> FALSE | H24: 568.35 | K24: 0 | L24: =IF(C24="","",IF(C24<=5,"Night (00-05)",IF(C24<=11,"Morning (06-11)",IF(C24<=16,"Afternoon (12-16)",IF(C24<=20,"Evening (17-20)","Late (21-23)"))))) -> Evening (17-20)
A25: ORD_10024 | B25: 46315 | C25: 13 | D25: Home Cleaning | E25: Zone South | F25: Completed | G25: =TRUE() -> TRUE | H25: 933.11 | I25: 4 | J25: 28 | K25: 0 | L25: =IF(C25="","",IF(C25<=5,"Night (00-05)",IF(C25<=11,"Morning (06-11)",IF(C25<=16,"Afternoon (12-16)",IF(C25<=20,"Evening (17-20)","Late (21-23)"))))) -> Afternoon (12-16)
A26: ORD_10025 | B26: 46317 | C26: 21 | D26: Home Cleaning | E26: Zone West | F26: Completed | G26: =TRUE() -> TRUE | H26: 1364.62 | I26: 3 | J26: 26 | K26: 0 | L26: =IF(C26="","",IF(C26<=5,"Night (00-05)",IF(C26<=11,"Morning (06-11)",IF(C26<=16,"Afternoon (12-16)",IF(C26<=20,"Evening (17-20)","Late (21-23)"))))) -> Late (21-23)
A27: ORD_10026 | B27: 46320 | C27: 2 | D27: Appliance Repair | E27: Zone South | F27: Completed | G27: =TRUE() -> TRUE | H27: 602.21 | I27: 5 | J27: 45 | K27: 0 | L27: =IF(C27="","",IF(C27<=5,"Night (00-05)",IF(C27<=11,"Morning (06-11)",IF(C27<=16,"Afternoon (12-16)",IF(C27<=20,"Evening (17-20)","Late (21-23)"))))) -> Night (00-05)
A28: ORD_10027 | B28: 46316 | C28: 19 | D28: Plumbing | E28: Zone East | F28: Cancelled_Customer | G28: =TRUE() -> TRUE | H28: 468.2 | K28: 0 | L28: =IF(C28="","",IF(C28<=5,"Night (00-05)",IF(C28<=11,"Morning (06-11)",IF(C28<=16,"Afternoon (12-16)",IF(C28<=20,"Evening (17-20)","Late (21-23)"))))) -> Evening (17-20)
A29: ORD_10028 | B29: 46321 | C29: 23 | D29: Appliance Repair | E29: Zone South | F29: Cancelled_Provider | G29: =FALSE() -> FALSE | H29: 547.35 | K29: 0 | L29: =IF(C29="","",IF(C29<=5,"Night (00-05)",IF(C29<=11,"Morning (06-11)",IF(C29<=16,"Afternoon (12-16)",IF(C29<=20,"Evening (17-20)","Late (21-23)"))))) -> Late (21-23)
A30: ORD_10029 | B30: 46320 | C30: 1 | D30: Salon Services | E30: Zone North | F30: Completed | G30: =TRUE() -> TRUE | H30: 539.11 | I30: 4 | J30: 53 | K30: 0 | L30: =IF(C30="","",IF(C30<=5,"Night (00-05)",IF(C30<=11,"Morning (06-11)",IF(C30<=16,"Afternoon (12-16)",IF(C30<=20,"Evening (17-20)","Late (21-23)"))))) -> Night (00-05)
A31: ORD_10030 | B31: 46319 | C31: 14 | D31: Home Cleaning | E31: Zone South | F31: Cancelled_Customer | G31: =TRUE() -> TRUE | H31: 1081.64 | K31: 0 | L31: =IF(C31="","",IF(C31<=5,"Night (00-05)",IF(C31<=11,"Morning (06-11)",IF(C31<=16,"Afternoon (12-16)",IF(C31<=20,"Evening (17-20)","Late (21-23)"))))) -> Afternoon (12-16)
A32: ORD_10031 | B32: 46319 | C32: 17 | D32: Home Cleaning | E32: Zone West | F32: Completed | G32: =TRUE() -> TRUE | H32: 1259.16 | I32: 5 | J32: 40 | K32: 0 | L32: =IF(C32="","",IF(C32<=5,"Night (00-05)",IF(C32<=11,"Morning (06-11)",IF(C32<=16,"Afternoon (12-16)",IF(C32<=20,"Evening (17-20)","Late (21-23)"))))) -> Evening (17-20)
A33: ORD_10032 | B33: 46317 | C33: 0 | D33: Salon Services | E33: Zone West | F33: Completed | G33: =TRUE() -> TRUE | H33: 603.7 | I33: 4 | J33: 49 | K33: 0 | L33: =IF(C33="","",IF(C33<=5,"Night (00-05)",IF(C33<=11,"Morning (06-11)",IF(C33<=16,"Afternoon (12-16)",IF(C33<=20,"Evening (17-20)","Late (21-23)"))))) -> Night (00-05)
A34: ORD_10033 | B34: 46322 | C34: 4 | D34: Home Cleaning | E34: Zone North | F34: Completed | G34: =TRUE() -> TRUE | H34: 1175.34 | I34: 5 | J34: 28 | K34: 0 | L34: =IF(C34="","",IF(C34<=5,"Night (00-05)",IF(C34<=11,"Morning (06-11)",IF(C34<=16,"Afternoon (12-16)",IF(C34<=20,"Evening (17-20)","Late (21-23)"))))) -> Night (00-05)
A35: ORD_10034 | B35: 46316 | C35: 3 | D35: Appliance Repair | E35: Zone West | F35: Completed | G35: =TRUE() -> TRUE | H35: 815.87 | I35: 1 | J35: 53 | K35: 0 | L35: =IF(C35="","",IF(C35<=5,"Night (00-05)",IF(C35<=11,"Morning (06-11)",IF(C35<=16,"Afternoon (12-16)",IF(C35<=20,"Evening (17-20)","Late (21-23)"))))) -> Night (00-05)
A36: ORD_10035 | B36: 46321 | C36: 23 | D36: Home Cleaning | E36: Zone South | F36: Cancelled_Customer | G36: =TRUE() -> TRUE | H36: 984.13 | K36: 0 | L36: =IF(C36="","",IF(C36<=5,"Night (00-05)",IF(C36<=11,"Morning (06-11)",IF(C36<=16,"Afternoon (12-16)",IF(C36<=20,"Evening (17-20)","Late (21-23)"))))) -> Late (21-23)
A37: ORD_10036 | B37: 46320 | C37: 23 | D37: Appliance Repair | E37: Zone East | F37: Completed | G37: =TRUE() -> TRUE | H37: 500.8 | I37: 4 | J37: 36 | K37: 0 | L37: =IF(C37="","",IF(C37<=5,"Night (00-05)",IF(C37<=11,"Morning (06-11)",IF(C37<=16,"Afternoon (12-16)",IF(C37<=20,"Evening (17-20)","Late (21-23)"))))) -> Late (21-23)
A38: ORD_10037 | B38: 46318 | C38: 3 | D38: Home Cleaning | E38: Zone West | F38: Completed | G38: =TRUE() -> TRUE | H38: 1379.54 | I38: 5 | J38: 41 | K38: 0 | L38: =IF(C38="","",IF(C38<=5,"Night (00-05)",IF(C38<=11,"Morning (06-11)",IF(C38<=16,"Afternoon (12-16)",IF(C38<=20,"Evening (17-20)","Late (21-23)"))))) -> Night (00-05)
A39: ORD_10038 | B39: 46321 | C39: 6 | D39: Plumbing | E39: Zone West | F39: Completed | G39: =TRUE() -> TRUE | H39: 523.36 | I39: 4 | J39: 29 | K39: 0 | L39: =IF(C39="","",IF(C39<=5,"Night (00-05)",IF(C39<=11,"Morning (06-11)",IF(C39<=16,"Afternoon (12-16)",IF(C39<=20,"Evening (17-20)","Late (21-23)"))))) -> Morning (06-11)
A40: ORD_10039 | B40: 46321 | C40: 19 | D40: Plumbing | E40: Zone South | F40: Completed | G40: =TRUE() -> TRUE | H40: 315.73 | I40: 5 | J40: 22 | K40: 0 | L40: =IF(C40="","",IF(C40<=5,"Night (00-05)",IF(C40<=11,"Morning (06-11)",IF(C40<=16,"Afternoon (12-16)",IF(C40<=20,"Evening (17-20)","Late (21-23)"))))) -> Evening (17-20)
...

Sheet Notes
A1: Notes, definitions and assumptions
A3: Source | B3: marketplace_orders_202610300200.csv – 1,000 orders, 20 Oct 2026 to 27 Oct 2026, 4 categories × 4 zones. Exported from DBeaver (table marketplace_orders).
A4: How to refresh | B4: Paste a new export into Data!A:K (same 11 columns, header in row 1, up to 5,000 rows). Every sheet recalculates. If new dates appear, add rows to the Daily sheet (copy the last row down). Column L (time_band) is a formula – leave it.
A5: Fulfillment rate | B5: Completed ÷ all orders.
A6: Cancellation rate | B6: (Cancelled_Customer + Cancelled_Provider) ÷ all orders.
A7: Unassigned % / vendor availability | B7: Orders with partner_assigned = FALSE ÷ orders. Partner availability = 1 − Unassigned %. The data has no partner IDs, so availability is measured from assignment outcomes, not from partner headcount.
A8: Avg TAT / SLA breach % | B8: TAT exists only for Completed orders, so both use completed orders as the denominator. is_sla_breach is taken as supplied (all breaches have TAT ≥ 66 min; no order under 60 min is flagged); the SLA limit itself is not in the data.
A9: Revenue at risk | B9: Sum of order_value for cancelled orders (currency as in source; not specified).
A10: Time bands | B10: Night 00–05 · Morning 06–11 · Afternoon 12–16 · Evening 17–20 · Late 21–23 (hour of order_hour).
A11: Alert thresholds | B11: ASSUMPTION: 10%/15% unassigned and 3%/5% SLA breach are illustrative targets (Alerts!B4:B8, editable). Cells under the minimum order count show LOW VOLUME.
A12: Data-quality flag | B12: 21 orders are Completed with partner_assigned = FALSE (all in Zone East, avg TAT ≈ 65 min). Likely a partner was found late and the flag was not updated – worth confirming with the data owner.
A13: Partial days | B13: First and last dates in the export have far fewer orders than the rest; treat their day-over-day changes with caution.
A14: Time zone | B14: order_hour has no stated time zone. The night-time demand peak is unusual for home services – confirm whether it is UTC.
A15: Findings text | B15: The 'Key findings' block on Dashboard is a static snapshot written from this export; KPI tiles, tables, charts and alert severities are live.
